2025-06-20 13:23:29,414 - __main__ - INFO - Database initialized successfully
2025-06-20 13:23:29,414 - __main__ - INFO - Starting bot...
2025-06-20 13:23:30,041 - TeleBot - ERROR - Threaded polling exception: A request to the Telegram API was unsuccessful. Error code: 409. Description: Conflict: can't use getUpdates method while webhook is active; use deleteWebhook to delete the webhook first
2025-06-20 13:23:30,045 - TeleBot - ERROR - Exception traceback:
Traceback (most recent call last):
  File "C:\Users\User\OneDrive\Desktop\TgBot\.venv\Lib\site-packages\telebot\__init__.py", line 1234, in __threaded_polling
    polling_thread.raise_exceptions()
    ~~~~~~~~~~~~~~~~~~~~~~~~~~~~~~~^^
  File "C:\Users\User\OneDrive\Desktop\TgBot\.venv\Lib\site-packages\telebot\util.py", line 111, in raise_exceptions
    raise self.exception_info
  File "C:\Users\User\OneDrive\Desktop\TgBot\.venv\Lib\site-packages\telebot\util.py", line 93, in run
    task(*args, **kwargs)
    ~~~~^^^^^^^^^^^^^^^^^
  File "C:\Users\User\OneDrive\Desktop\TgBot\.venv\Lib\site-packages\telebot\__init__.py", line 688, in __retrieve_updates
    updates = self.get_updates(offset=(self.last_update_id + 1),
                               allowed_updates=allowed_updates,
                               timeout=timeout, long_polling_timeout=long_polling_timeout)
  File "C:\Users\User\OneDrive\Desktop\TgBot\.venv\Lib\site-packages\telebot\__init__.py", line 660, in get_updates
    json_updates = apihelper.get_updates(
        self.token, offset=offset, limit=limit, timeout=timeout, allowed_updates=allowed_updates,
        long_polling_timeout=long_polling_timeout)
  File "C:\Users\User\OneDrive\Desktop\TgBot\.venv\Lib\site-packages\telebot\apihelper.py", line 332, in get_updates
    return _make_request(token, method_url, params=payload)
  File "C:\Users\User\OneDrive\Desktop\TgBot\.venv\Lib\site-packages\telebot\apihelper.py", line 168, in _make_request
    json_result = _check_result(method_name, result)
  File "C:\Users\User\OneDrive\Desktop\TgBot\.venv\Lib\site-packages\telebot\apihelper.py", line 195, in _check_result
    raise ApiTelegramException(method_name, result, result_json)
telebot.apihelper.ApiTelegramException: A request to the Telegram API was unsuccessful. Error code: 409. Description: Conflict: can't use getUpdates method while webhook is active; use deleteWebhook to delete the webhook first

2025-06-20 13:23:33,401 - TeleBot - ERROR - Threaded polling exception: A request to the Telegram API was unsuccessful. Error code: 409. Description: Conflict: can't use getUpdates method while webhook is active; use deleteWebhook to delete the webhook first
2025-06-20 13:23:33,404 - TeleBot - ERROR - Exception traceback:
Traceback (most recent call last):
  File "C:\Users\User\OneDrive\Desktop\TgBot\.venv\Lib\site-packages\telebot\__init__.py", line 1234, in __threaded_polling
    polling_thread.raise_exceptions()
    ~~~~~~~~~~~~~~~~~~~~~~~~~~~~~~~^^
  File "C:\Users\User\OneDrive\Desktop\TgBot\.venv\Lib\site-packages\telebot\util.py", line 111, in raise_exceptions
    raise self.exception_info
  File "C:\Users\User\OneDrive\Desktop\TgBot\.venv\Lib\site-packages\telebot\util.py", line 93, in run
    task(*args, **kwargs)
    ~~~~^^^^^^^^^^^^^^^^^
  File "C:\Users\User\OneDrive\Desktop\TgBot\.venv\Lib\site-packages\telebot\__init__.py", line 688, in __retrieve_updates
    updates = self.get_updates(offset=(self.last_update_id + 1),
                               allowed_updates=allowed_updates,
                               timeout=timeout, long_polling_timeout=long_polling_timeout)
  File "C:\Users\User\OneDrive\Desktop\TgBot\.venv\Lib\site-packages\telebot\__init__.py", line 660, in get_updates
    json_updates = apihelper.get_updates(
        self.token, offset=offset, limit=limit, timeout=timeout, allowed_updates=allowed_updates,
        long_polling_timeout=long_polling_timeout)
  File "C:\Users\User\OneDrive\Desktop\TgBot\.venv\Lib\site-packages\telebot\apihelper.py", line 332, in get_updates
    return _make_request(token, method_url, params=payload)
  File "C:\Users\User\OneDrive\Desktop\TgBot\.venv\Lib\site-packages\telebot\apihelper.py", line 168, in _make_request
    json_result = _check_result(method_name, result)
  File "C:\Users\User\OneDrive\Desktop\TgBot\.venv\Lib\site-packages\telebot\apihelper.py", line 195, in _check_result
    raise ApiTelegramException(method_name, result, result_json)
telebot.apihelper.ApiTelegramException: A request to the Telegram API was unsuccessful. Error code: 409. Description: Conflict: can't use getUpdates method while webhook is active; use deleteWebhook to delete the webhook first

2025-06-20 13:23:34,012 - TeleBot - ERROR - Threaded polling exception: A request to the Telegram API was unsuccessful. Error code: 409. Description: Conflict: can't use getUpdates method while webhook is active; use deleteWebhook to delete the webhook first
2025-06-20 13:23:34,015 - TeleBot - ERROR - Exception traceback:
Traceback (most recent call last):
  File "C:\Users\User\OneDrive\Desktop\TgBot\.venv\Lib\site-packages\telebot\__init__.py", line 1234, in __threaded_polling
    polling_thread.raise_exceptions()
    ~~~~~~~~~~~~~~~~~~~~~~~~~~~~~~~^^
  File "C:\Users\User\OneDrive\Desktop\TgBot\.venv\Lib\site-packages\telebot\util.py", line 111, in raise_exceptions
    raise self.exception_info
  File "C:\Users\User\OneDrive\Desktop\TgBot\.venv\Lib\site-packages\telebot\util.py", line 93, in run
    task(*args, **kwargs)
    ~~~~^^^^^^^^^^^^^^^^^
  File "C:\Users\User\OneDrive\Desktop\TgBot\.venv\Lib\site-packages\telebot\__init__.py", line 688, in __retrieve_updates
    updates = self.get_updates(offset=(self.last_update_id + 1),
                               allowed_updates=allowed_updates,
                               timeout=timeout, long_polling_timeout=long_polling_timeout)
  File "C:\Users\User\OneDrive\Desktop\TgBot\.venv\Lib\site-packages\telebot\__init__.py", line 660, in get_updates
    json_updates = apihelper.get_updates(
        self.token, offset=offset, limit=limit, timeout=timeout, allowed_updates=allowed_updates,
        long_polling_timeout=long_polling_timeout)
  File "C:\Users\User\OneDrive\Desktop\TgBot\.venv\Lib\site-packages\telebot\apihelper.py", line 332, in get_updates
    return _make_request(token, method_url, params=payload)
  File "C:\Users\User\OneDrive\Desktop\TgBot\.venv\Lib\site-packages\telebot\apihelper.py", line 168, in _make_request
    json_result = _check_result(method_name, result)
  File "C:\Users\User\OneDrive\Desktop\TgBot\.venv\Lib\site-packages\telebot\apihelper.py", line 195, in _check_result
    raise ApiTelegramException(method_name, result, result_json)
telebot.apihelper.ApiTelegramException: A request to the Telegram API was unsuccessful. Error code: 409. Description: Conflict: can't use getUpdates method while webhook is active; use deleteWebhook to delete the webhook first

2025-06-20 13:23:38,099 - TeleBot - ERROR - Threaded polling exception: A request to the Telegram API was unsuccessful. Error code: 409. Description: Conflict: can't use getUpdates method while webhook is active; use deleteWebhook to delete the webhook first
2025-06-20 13:23:38,101 - TeleBot - ERROR - Exception traceback:
Traceback (most recent call last):
  File "C:\Users\User\OneDrive\Desktop\TgBot\.venv\Lib\site-packages\telebot\__init__.py", line 1234, in __threaded_polling
    polling_thread.raise_exceptions()
    ~~~~~~~~~~~~~~~~~~~~~~~~~~~~~~~^^
  File "C:\Users\User\OneDrive\Desktop\TgBot\.venv\Lib\site-packages\telebot\util.py", line 111, in raise_exceptions
    raise self.exception_info
  File "C:\Users\User\OneDrive\Desktop\TgBot\.venv\Lib\site-packages\telebot\util.py", line 93, in run
    task(*args, **kwargs)
    ~~~~^^^^^^^^^^^^^^^^^
  File "C:\Users\User\OneDrive\Desktop\TgBot\.venv\Lib\site-packages\telebot\__init__.py", line 688, in __retrieve_updates
    updates = self.get_updates(offset=(self.last_update_id + 1),
                               allowed_updates=allowed_updates,
                               timeout=timeout, long_polling_timeout=long_polling_timeout)
  File "C:\Users\User\OneDrive\Desktop\TgBot\.venv\Lib\site-packages\telebot\__init__.py", line 660, in get_updates
    json_updates = apihelper.get_updates(
        self.token, offset=offset, limit=limit, timeout=timeout, allowed_updates=allowed_updates,
        long_polling_timeout=long_polling_timeout)
  File "C:\Users\User\OneDrive\Desktop\TgBot\.venv\Lib\site-packages\telebot\apihelper.py", line 332, in get_updates
    return _make_request(token, method_url, params=payload)
  File "C:\Users\User\OneDrive\Desktop\TgBot\.venv\Lib\site-packages\telebot\apihelper.py", line 168, in _make_request
    json_result = _check_result(method_name, result)
  File "C:\Users\User\OneDrive\Desktop\TgBot\.venv\Lib\site-packages\telebot\apihelper.py", line 195, in _check_result
    raise ApiTelegramException(method_name, result, result_json)
telebot.apihelper.ApiTelegramException: A request to the Telegram API was unsuccessful. Error code: 409. Description: Conflict: can't use getUpdates method while webhook is active; use deleteWebhook to delete the webhook first

2025-06-20 13:23:40,237 - TeleBot - ERROR - Threaded polling exception: A request to the Telegram API was unsuccessful. Error code: 409. Description: Conflict: can't use getUpdates method while webhook is active; use deleteWebhook to delete the webhook first
2025-06-20 13:23:40,241 - TeleBot - ERROR - Exception traceback:
Traceback (most recent call last):
  File "C:\Users\User\OneDrive\Desktop\TgBot\.venv\Lib\site-packages\telebot\__init__.py", line 1234, in __threaded_polling
    polling_thread.raise_exceptions()
    ~~~~~~~~~~~~~~~~~~~~~~~~~~~~~~~^^
  File "C:\Users\User\OneDrive\Desktop\TgBot\.venv\Lib\site-packages\telebot\util.py", line 111, in raise_exceptions
    raise self.exception_info
  File "C:\Users\User\OneDrive\Desktop\TgBot\.venv\Lib\site-packages\telebot\util.py", line 93, in run
    task(*args, **kwargs)
    ~~~~^^^^^^^^^^^^^^^^^
  File "C:\Users\User\OneDrive\Desktop\TgBot\.venv\Lib\site-packages\telebot\__init__.py", line 688, in __retrieve_updates
    updates = self.get_updates(offset=(self.last_update_id + 1),
                               allowed_updates=allowed_updates,
                               timeout=timeout, long_polling_timeout=long_polling_timeout)
  File "C:\Users\User\OneDrive\Desktop\TgBot\.venv\Lib\site-packages\telebot\__init__.py", line 660, in get_updates
    json_updates = apihelper.get_updates(
        self.token, offset=offset, limit=limit, timeout=timeout, allowed_updates=allowed_updates,
        long_polling_timeout=long_polling_timeout)
  File "C:\Users\User\OneDrive\Desktop\TgBot\.venv\Lib\site-packages\telebot\apihelper.py", line 332, in get_updates
    return _make_request(token, method_url, params=payload)
  File "C:\Users\User\OneDrive\Desktop\TgBot\.venv\Lib\site-packages\telebot\apihelper.py", line 168, in _make_request
    json_result = _check_result(method_name, result)
  File "C:\Users\User\OneDrive\Desktop\TgBot\.venv\Lib\site-packages\telebot\apihelper.py", line 195, in _check_result
    raise ApiTelegramException(method_name, result, result_json)
telebot.apihelper.ApiTelegramException: A request to the Telegram API was unsuccessful. Error code: 409. Description: Conflict: can't use getUpdates method while webhook is active; use deleteWebhook to delete the webhook first

2025-06-20 13:23:44,330 - TeleBot - ERROR - Threaded polling exception: A request to the Telegram API was unsuccessful. Error code: 409. Description: Conflict: can't use getUpdates method while webhook is active; use deleteWebhook to delete the webhook first
2025-06-20 13:23:44,335 - TeleBot - ERROR - Exception traceback:
Traceback (most recent call last):
  File "C:\Users\User\OneDrive\Desktop\TgBot\.venv\Lib\site-packages\telebot\__init__.py", line 1234, in __threaded_polling
    polling_thread.raise_exceptions()
    ~~~~~~~~~~~~~~~~~~~~~~~~~~~~~~~^^
  File "C:\Users\User\OneDrive\Desktop\TgBot\.venv\Lib\site-packages\telebot\util.py", line 111, in raise_exceptions
    raise self.exception_info
  File "C:\Users\User\OneDrive\Desktop\TgBot\.venv\Lib\site-packages\telebot\util.py", line 93, in run
    task(*args, **kwargs)
    ~~~~^^^^^^^^^^^^^^^^^
  File "C:\Users\User\OneDrive\Desktop\TgBot\.venv\Lib\site-packages\telebot\__init__.py", line 688, in __retrieve_updates
    updates = self.get_updates(offset=(self.last_update_id + 1),
                               allowed_updates=allowed_updates,
                               timeout=timeout, long_polling_timeout=long_polling_timeout)
  File "C:\Users\User\OneDrive\Desktop\TgBot\.venv\Lib\site-packages\telebot\__init__.py", line 660, in get_updates
    json_updates = apihelper.get_updates(
        self.token, offset=offset, limit=limit, timeout=timeout, allowed_updates=allowed_updates,
        long_polling_timeout=long_polling_timeout)
  File "C:\Users\User\OneDrive\Desktop\TgBot\.venv\Lib\site-packages\telebot\apihelper.py", line 332, in get_updates
    return _make_request(token, method_url, params=payload)
  File "C:\Users\User\OneDrive\Desktop\TgBot\.venv\Lib\site-packages\telebot\apihelper.py", line 168, in _make_request
    json_result = _check_result(method_name, result)
  File "C:\Users\User\OneDrive\Desktop\TgBot\.venv\Lib\site-packages\telebot\apihelper.py", line 195, in _check_result
    raise ApiTelegramException(method_name, result, result_json)
telebot.apihelper.ApiTelegramException: A request to the Telegram API was unsuccessful. Error code: 409. Description: Conflict: can't use getUpdates method while webhook is active; use deleteWebhook to delete the webhook first

2025-06-20 13:23:52,521 - TeleBot - ERROR - Threaded polling exception: A request to the Telegram API was unsuccessful. Error code: 409. Description: Conflict: can't use getUpdates method while webhook is active; use deleteWebhook to delete the webhook first
2025-06-20 13:23:52,535 - TeleBot - ERROR - Exception traceback:
Traceback (most recent call last):
  File "C:\Users\User\OneDrive\Desktop\TgBot\.venv\Lib\site-packages\telebot\__init__.py", line 1234, in __threaded_polling
    polling_thread.raise_exceptions()
    ~~~~~~~~~~~~~~~~~~~~~~~~~~~~~~~^^
  File "C:\Users\User\OneDrive\Desktop\TgBot\.venv\Lib\site-packages\telebot\util.py", line 111, in raise_exceptions
    raise self.exception_info
  File "C:\Users\User\OneDrive\Desktop\TgBot\.venv\Lib\site-packages\telebot\util.py", line 93, in run
    task(*args, **kwargs)
    ~~~~^^^^^^^^^^^^^^^^^
  File "C:\Users\User\OneDrive\Desktop\TgBot\.venv\Lib\site-packages\telebot\__init__.py", line 688, in __retrieve_updates
    updates = self.get_updates(offset=(self.last_update_id + 1),
                               allowed_updates=allowed_updates,
                               timeout=timeout, long_polling_timeout=long_polling_timeout)
  File "C:\Users\User\OneDrive\Desktop\TgBot\.venv\Lib\site-packages\telebot\__init__.py", line 660, in get_updates
    json_updates = apihelper.get_updates(
        self.token, offset=offset, limit=limit, timeout=timeout, allowed_updates=allowed_updates,
        long_polling_timeout=long_polling_timeout)
  File "C:\Users\User\OneDrive\Desktop\TgBot\.venv\Lib\site-packages\telebot\apihelper.py", line 332, in get_updates
    return _make_request(token, method_url, params=payload)
  File "C:\Users\User\OneDrive\Desktop\TgBot\.venv\Lib\site-packages\telebot\apihelper.py", line 168, in _make_request
    json_result = _check_result(method_name, result)
  File "C:\Users\User\OneDrive\Desktop\TgBot\.venv\Lib\site-packages\telebot\apihelper.py", line 195, in _check_result
    raise ApiTelegramException(method_name, result, result_json)
telebot.apihelper.ApiTelegramException: A request to the Telegram API was unsuccessful. Error code: 409. Description: Conflict: can't use getUpdates method while webhook is active; use deleteWebhook to delete the webhook first

2025-06-20 13:44:05,537 - __main__ - ERROR - Database initialization error: table access_keys has no column named created_at
2025-06-20 13:44:05,537 - __main__ - CRITICAL - Fatal error: table access_keys has no column named created_at
2025-06-20 13:46:35,041 - __main__ - ERROR - Database initialization error: table access_keys has no column named created_at
2025-06-20 13:46:35,041 - __main__ - CRITICAL - Fatal error: table access_keys has no column named created_at
2025-06-20 13:50:49,369 - __main__ - ERROR - Database initialization error: table access_keys has no column named created_at
2025-06-20 13:50:49,369 - __main__ - CRITICAL - Fatal error: table access_keys has no column named created_at
2025-06-20 14:22:06,876 - __main__ - ERROR - Database initialization error: table access_keys has no column named created_at
2025-06-20 14:22:06,878 - __main__ - CRITICAL - Fatal error: table access_keys has no column named created_at
2025-06-20 14:22:58,544 - __main__ - ERROR - Database initialization error: table access_keys has no column named created_at
2025-06-20 14:22:58,544 - __main__ - CRITICAL - Fatal error: table access_keys has no column named created_at
